Workbook

Sheet Scenario comparison
A1: Scenario comparison
A2: Business plan · Base
A4: Variable / dimension | B4: Value | C4: Value > Growth | D4: Value > Low-volume stress
A5: Monthly briefing volume | B5: =100 -> 100 | C5: =1000 -> 1000 | D5: =10 -> 10
A6: Modeled monthly revenue | B6: ='Scenario comparison'!B5*'Model inputs'!B6 -> 88 | C6: ='Scenario comparison'!C5*'Model inputs'!B7 -> 880 | D6: ='Scenario comparison'!D5*'Model inputs'!B8 -> 8.8
A7: Modeled monthly variable cost | B7: ='Scenario comparison'!B5*'Model inputs'!B24 -> 5.213 | C7: ='Scenario comparison'!C5*'Model inputs'!B25 -> 52.13 | D7: ='Scenario comparison'!D5*'Model inputs'!B26 -> 0.5213
A8: Monthly fixed costs | B8: ='Model inputs'!B15+'Model inputs'!B18 -> 15 | C8: ='Model inputs'!B16+'Model inputs'!B19 -> 15 | D8: ='Model inputs'!B17+'Model inputs'!B20 -> 15
A9: Modeled monthly profit | B9: ='Model inputs'!B12-'Scenario comparison'!B8 -> 67.787 | C9: ='Model inputs'!B13-'Scenario comparison'!C8 -> 812.87 | D9: ='Model inputs'!B14-'Scenario comparison'!D8 -> -6.7213
A10: Blended gross margin | B10: =IFERROR('Model inputs'!B9/'Model inputs'!B6,"") -> 0.94076136 | C10: =IFERROR('Model inputs'!B10/'Model inputs'!B7,"") -> 0.94076136 | D10: =IFERROR('Model inputs'!B11/'Model inputs'!B8,"") -> 0.94076136
A11: Break-even briefings | B11: =IF(IF(IF(ISERROR('Model inputs'!B9>0),'Model inputs'!B9>0,IF('Model inputs'!B9="","",'Model inputs'!B9>0))="",FALSE,IF(ISERROR('Model inputs'!B9>0),'Model inputs'!B9>0,IF('Model inputs'!B9="","",'Model inputs'!B9>0))),CEILING('Scenario comparison'!B8/'Model inputs'!B9,1),"") -> 19 | C11: =IF(IF(IF(ISERROR('Model inputs'!B10>0),'Model inputs'!B10>0,IF('Model inputs'!B10="","",'Model inputs'!B10>0))="",FALSE,IF(ISERROR('Model inputs'!B10>0),'Model inputs'!B10>0,IF('Model inputs'!B10="","",'Model inputs'!B10>0))),CEILING('Scenario comparison'!C8/'Model inputs'!B10,1),"") -> 19 | D11: =IF(IF(IF(ISERROR('Model inputs'!B11>0),'Model inputs'!B11>0,IF('Model inputs'!B11="","",'Model inputs'!B11>0))="",FALSE,IF(ISERROR('Model inputs'!B11>0),'Model inputs'!B11>0,IF('Model inputs'!B11="","",'Model inputs'!B11>0))),CEILING('Scenario comparison'!D8/'Model inputs'!B11,1),"") -> 19
A12: Runway months | B12: =IF(IF(IF(ISERROR('Scenario comparison'!B9<0),'Scenario comparison'!B9<0,IF('Scenario comparison'!B9="","",'Scenario comparison'!B9<0))="",FALSE,IF(ISERROR('Scenario comparison'!B9<0),'Scenario comparison'!B9<0,IF('Scenario comparison'!B9="","",'Scenario comparison'!B9<0))),'Model inputs'!B21/(-'Scenario comparison'!B9),"") | C12: =IF(IF(IF(ISERROR('Scenario comparison'!C9<0),'Scenario comparison'!C9<0,IF('Scenario comparison'!C9="","",'Scenario comparison'!C9<0))="",FALSE,IF(ISERROR('Scenario comparison'!C9<0),'Scenario comparison'!C9<0,IF('Scenario comparison'!C9="","",'Scenario comparison'!C9<0))),'Model inputs'!B22/(-'Scenario comparison'!C9),"") | D12: =IF(IF(IF(ISERROR('Scenario comparison'!D9<0),'Scenario comparison'!D9<0,IF('Scenario comparison'!D9="","",'Scenario comparison'!D9<0))="",FALSE,IF(ISERROR('Scenario comparison'!D9<0),'Scenario comparison'!D9<0,IF('Scenario comparison'!D9="","",'Scenario comparison'!D9<0))),'Model inputs'!B23/(-'Scenario comparison'!D9),"") -> 297.56148
A13: Runway interpretation | B13: =IF(IF(IF(ISERROR('Scenario comparison'!B9<0),'Scenario comparison'!B9<0,IF('Scenario comparison'!B9="","",'Scenario comparison'!B9<0))="",FALSE,IF(ISERROR('Scenario comparison'!B9<0),'Scenario comparison'!B9<0,IF('Scenario comparison'!B9="","",'Scenario comparison'!B9<0))),"Finite runway at constant monthly burn","No finite exhaustion runway at nonnegative cash flow") -> No finite exhaustion runway at nonnegative cash flow | C13: =IF(IF(IF(ISERROR('Scenario comparison'!C9<0),'Scenario comparison'!C9<0,IF('Scenario comparison'!C9="","",'Scenario comparison'!C9<0))="",FALSE,IF(ISERROR('Scenario comparison'!C9<0),'Scenario comparison'!C9<0,IF('Scenario comparison'!C9="","",'Scenario comparison'!C9<0))),"Finite runway at constant monthly burn","No finite exhaustion runway at nonnegative cash flow") -> No finite exhaustion runway at nonnegative cash flow | D13: =IF(IF(IF(ISERROR('Scenario comparison'!D9<0),'Scenario comparison'!D9<0,IF('Scenario comparison'!D9="","",'Scenario comparison'!D9<0))="",FALSE,IF(ISERROR('Scenario comparison'!D9<0),'Scenario comparison'!D9<0,IF('Scenario comparison'!D9="","",'Scenario comparison'!D9<0))),"Finite runway at constant monthly burn","No finite exhaustion runway at nonnegative cash flow") -> Finite runway at constant monthly burn

Sheet Model inputs
A1: Model inputs
A2: Integration values are aggregated snapshots; raw source records are not included.
A4: Variables
A5: Variable / segment | B5: Value
A6: Blended price per briefing · Base | B6: ='Model inputs'!B35*'Model inputs'!B44+'Model inputs'!B34*'Model inputs'!B43 -> 0.88
A7: Blended price per briefing · Growth | B7: ='Model inputs'!B38*'Model inputs'!B47+'Model inputs'!B37*'Model inputs'!B46 -> 0.88
A8: Blended price per briefing · Low-volume stress | B8: ='Model inputs'!B41*'Model inputs'!B50+'Model inputs'!B40*'Model inputs'!B49 -> 0.88
A9: Contribution per briefing · Base | B9: ='Model inputs'!B6-'Model inputs'!B24 -> 0.82787
A10: Contribution per briefing · Growth | B10: ='Model inputs'!B7-'Model inputs'!B25 -> 0.82787
A11: Contribution per briefing · Low-volume stress | B11: ='Model inputs'!B8-'Model inputs'!B26 -> 0.82787
A12: Modeled monthly gross profit · Base | B12: ='Scenario comparison'!B6-'Scenario comparison'!B7 -> 82.787
A13: Modeled monthly gross profit · Growth | B13: ='Scenario comparison'!C6-'Scenario comparison'!C7 -> 827.87
A14: Modeled monthly gross profit · Low-volume stress | B14: ='Scenario comparison'!D6-'Scenario comparison'!D7 -> 8.2787
A15: Monthly hosting · Base | B15: =15 -> 15
A16: Monthly hosting · Growth | B16: =15 -> 15
A17: Monthly hosting · Low-volume stress | B17: =15 -> 15
A18: Monthly monitoring · Base | B18: =0 -> 0
A19: Monthly monitoring · Growth | B19: =0 -> 0
A20: Monthly monitoring · Low-volume stress | B20: =0 -> 0
A21: Starting cash · Base | B21: =2000 -> 2000
A22: Starting cash · Growth | B22: =2000 -> 2000
A23: Starting cash · Low-volume stress | B23: =2000 -> 2000
A24: Variable cost per briefing · Base | B24: ='Model inputs'!B27+'Model inputs'!B30 -> 0.05213
A25: Variable cost per briefing · Growth | B25: ='Model inputs'!B28+'Model inputs'!B31 -> 0.05213
A26: Variable cost per briefing · Low-volume stress | B26: ='Model inputs'!B29+'Model inputs'!B32 -> 0.05213
A27: API cost per briefing · Base | B27: ='Model inputs'!B51*'Model inputs'!B54*'Model inputs'!B57 -> 0.052
A28: API cost per briefing · Growth | B28: ='Model inputs'!B52*'Model inputs'!B55*'Model inputs'!B58 -> 0.052
A29: API cost per briefing · Low-volume stress | B29: ='Model inputs'!B53*'Model inputs'!B56*'Model inputs'!B59 -> 0.052
A30: LLM cost per briefing · Base | B30: ='Model inputs'!B60*'Model inputs'!B57 -> 0.00013
A31: LLM cost per briefing · Growth | B31: ='Model inputs'!B61*'Model inputs'!B58 -> 0.00013
A32: LLM cost per briefing · Low-volume stress | B32: ='Model inputs'!B62*'Model inputs'!B59 -> 0.00013
A33: Price per briefing | B33: 0
A34: Price per briefing > Business | B34: =2.2 -> 2.2
A35: Price per briefing > Student | B35: =0.55 -> 0.55
A36: Price per briefing | B36: 0
A37: Price per briefing > Business | B37: =2.2 -> 2.2
A38: Price per briefing > Student | B38: =0.55 -> 0.55
A39: Price per briefing | B39: 0
A40: Price per briefing > Business | B40: =2.2 -> 2.2
A41: Price per briefing > Student | B41: =0.55 -> 0.55
...
